Workbook

Sheet 11;50
A1: HORARIO PRE ESCOLAR 11:50
A5: Nro. | B5: ALUMNO | C5: CURSO | D5: FECHA INICIO | E5: FECHA FIN | F5: OBSERVACIONES | G5: AGOSTO | Z5: PLATOS VENDIDOS | AA5: PLATOS VENDIDOS EN BS
G6: L | H6: M | I6: M | J6: L | K6: M | L6: M | M6: J | N6: V | O6: L | P6: M | Q6: M | R6: J | S6: V | T6: L | U6: M | V6: M | W6: J | X6: V | Y6: L
G7: 1 | H7: 2 | I7: 3 | J7: 4 | K7: 5 | L7: 6 | M7: 7 | N7: 8 | O7: 9 | P7: 10 | Q7: 11 | R7: 12 | S7: 13 | T7: 14 | U7: 15 | V7: 16 | W7: 17 | X7: 18 | Y7: 19
G8: 3 | H8: 4 | I8: 5 | J8: 10 | K8: 11 | L8: 12 | M8: 13 | N8: 14 | O8: 17 | P8: 18 | Q8: 19 | R8: 20 | S8: 21 | T8: 24 | U8: 25 | V8: 26 | W8: 27 | X8: 28 | Y8: 31
A9: 1 | B9: ALEXANDER AESCHBACHER | C9: KINDER B | F9: NO JUGO/SOLO AGUA | J9: 1 | M9: 1 | N9: 1 | O9: 1 | Q9: 1 | T9: 1 | U9: 1 | V9: 1 | X9: 1 | Z9: =+SUM(G9:Y9) -> 9 | AA9: =+Z9*32 -> 288
A10: 2 | B10: ABIGAIL GONG PACO | C10: PRE K C | G10: 1 | H10: 1 | J10: 1 | M10: 1 | N10: 0 | O10: 1 | Q10: 1 | T10: 1 | W10: 0 | X10: 1 | Z10: =+SUM(G10:Y10) -> 8 | AA10: =+Z10*32 -> 256
A11: 3 | B11: AGUSTINA ROCA | C11: KINDER B | Z11: =+SUM(G11:Y11) -> 0 | AA11: =+Z11*32 -> 0
A12: 4 | B12: AINOA ARCE | C12: PRE K B | Z12: =+SUM(G12:Y12) -> 0 | AA12: =+Z12*32 -> 0
A13: 5 | B13: ALISON REBECA ALBA | C13: KINDER A | F13: NO PIPOCAS DE POLLO | G13: 1 | H13: 1 | J13: 1 | K13: 1 | L13: 1 | M13: 1 | N13: 1 | O13: 1 | P13: 0 | Q13: 1 | R13: 1 | S13: 0 | T13: 1 | U13: 1 | V13: 1 | W13: 1 | X13: 1 | Z13: =+SUM(G13:Y13) -> 15 | AA13: =+Z13*32 -> 480
A14: 6 | B14: AMELIE ANTELO | C14: KINDER C | Z14: =+SUM(G14:Y14) -> 0 | AA14: =+Z14*32 -> 0
A15: 7 | B15: ANA FABIA JIMENEZ | C15: KINDER A | P15: 1
A16: 8 | B16: ANA LUCIA ROSADO | C16: KINDER A | G16: 1 | H16: 1 | J16: 1 | K16: 1 | L16: 1 | M16: 1 | N16: 1 | O16: 1 | P16: 1 | Q16: 1 | R16: 1 | S16: 1 | T16: 1 | U16: 1 | V16: 1 | W16: 1 | X16: 1 | Z16: =+SUM(G16:Y16) -> 17 | AA16: =+Z16*32 -> 544
A17: 9 | B17: ANDIARA SUAREZ | C17: PRE K C | G17: 1 | J17: 1 | O17: 1 | U17: 1 | Z17: =+SUM(G17:Y17) -> 4 | AA17: =+Z17*32 -> 128
A18: 10 | B18: ANDRES BOWLES | C18: PRE K A | Z18: =+SUM(G18:Y18) -> 0 | AA18: =+Z18*32 -> 0
A19: 11 | B19: ANDRES NACIF | C19: PRE K C | G19: 1 | H19: 1 | J19: 1 | K19: 1 | L19: 1 | M19: 1 | N19: 1 | O19: 1 | P19: 1 | Q19: 1 | R19: 1 | T19: 1 | U19: 1 | V19: 1 | W19: 1 | X19: 1 | Z19: =+SUM(G19:Y19) -> 16 | AA19: =+Z19*32 -> 512
A20: 12 | B20: ANDRES SEAS | C20: PRE K A | L20: 1 | P20: 1 | R20: 1 | T20: 1 | V20: 1 | W20: 1 | Z20: =+SUM(G20:Y20) -> 6 | AA20: =+Z20*32 -> 192
A21: 13 | B21: ANTONELLA BERRENDERO | C21: KINDER A | Z21: =+SUM(G21:Y21) -> 0 | AA21: =+Z21*32 -> 0
A22: 14 | B22: ANTONELLA ROJAS | C22: KINDER C | F22: DEBE SNACKS DEL MES PASADO | Z22: =+SUM(G22:Y22) -> 0 | AA22: =+Z22*32 -> 0
A23: 15 | B23: ARIANNA TIRADO | C23: KINDER B | H23: 1 | J23: 1 | K23: 1 | L23: 1 | M23: 1 | N23: 1 | O23: 1 | P23: 1 | Q23: 1 | R23: 1 | S23: 1 | T23: 1 | U23: 1 | V23: 1 | W23: 1 | X23: 1 | Z23: =+SUM(G23:Y23) -> 16 | AA23: =+Z23*32 -> 512
A24: 16 | B24: BENJAMIN ARNEZ | C24: PRE K C | O24: 1 | Z24: =+SUM(G24:Y24) -> 1 | AA24: =+Z24*32 -> 32
A25: 17 | B25: BRUNA SOLJANCIC | C25: KINDER A | Z25: =+SUM(G25:Y25) -> 0 | AA25: =+Z25*32 -> 0
A26: 18 | B26: CALEB GONG PACO | C26: KINDER C | D26: . | G26: 1 | H26: 1 | N26: 1 | O26: 1 | Q26: 1 | T26: 1 | W26: 0 | X26: 1 | Z26: =+SUM(G26:Y26) -> 7 | AA26: =+Z26*32 -> 224
A27: 19 | B27: CATALINA ADAD | C27: PRE K B | Z27: =+SUM(G27:Y27) -> 0 | AA27: =+Z27*32 -> 0
A28: 20 | B28: CATALINA MORILLO | C28: KINDER A | Z28: =+SUM(G28:Y28) -> 0 | AA28: =+Z28*32 -> 0
A29: 21 | B29: CARMEN SOFIA SEJAS | C29: PRE K A | F29: ALMUERZO + MERIENDA | G29: 1 | H29: 1 | J29: 1 | K29: 1 | L29: 1 | M29: 1 | N29: 1 | O29: 1 | P29: 1 | Q29: 1 | R29: 1 | S29: 1 | T29: 1 | U29: 1 | V29: 1 | W29: 1 | X29: 1 | Z29: =+SUM(G29:Y29) -> 17 | AA29: =+Z29*32 -> 544
A30: 22 | B30: CAYETANA ARZABE | C30: PRE K C | O30: 1 | Z30: =+SUM(G30:Y30) -> 1 | AA30: =+Z30*32 -> 32
A31: 23 | B31: CELESTE BALCAZAR | C31: KINDER A | G31: 1 | H31: 1 | J31: 1 | K31: 1 | L31: 1 | M31: 1 | N31: 1 | O31: 1 | P31: 1 | Q31: 1 | R31: 1 | S31: 1 | T31: 1 | U31: 1 | V31: 1 | W31: 1 | X31: 1 | Z31: =+SUM(G31:Y31) -> 17 | AA31: =+Z31*32 -> 544
A32: 24 | B32: DARIO MUNDAKA | C32: PRE K C | J32: 1
A33: 25 | B33: DIEGO MARTINEZ | C33: KINDER A | F33: REGISTRO HASTA EL 30 DE SEPT | G33: 1 | H33: 1 | J33: 1 | K33: 1 | L33: 1 | M33: 1 | N33: 1 | O33: 1 | P33: 1 | Q33: 1 | R33: 1 | S33: 1 | T33: 1 | U33: 1 | V33: 1 | W33: 1 | X33: 1 | Z33: =+SUM(G33:Y33) -> 17 | AA33: =+Z33*32 -> 544
A34: 26 | B34: ELENOR ARAMAYO | C34: KINDER B | Z34: =+SUM(G34:Y34) -> 0 | AA34: =+Z34*32 -> 0
A35: 27 | B35: ELENA DAROCA | C35: PRE K A | H35: 1 | J35: 1 | O35: 1 | S35: 1 | W35: 1 | Z35: =+SUM(G35:Y35) -> 5 | AA35: =+Z35*32 -> 160
A36: 28 | B36: EMMA VEGA | C36: PRE K A | H36: 1 | Z36: =+SUM(G36:Y36) -> 1 | AA36: =+Z36*32 -> 32
A37: 29 | B37: ESTEBAN SPENCER | C37: PRE K B | Z37: =+SUM(G37:Y37) -> 0 | AA37: =+Z37*32 -> 0
A38: 30 | B38: HELENA BARBIERI | C38: KINDER C | F38: NO LACTEOS - NO GLUTEN | G38: 1 | H38: 1 | J38: 1 | K38: 1 | L38: 1 | M38: 1 | N38: 1 | O38: 1 | P38: 1 | Q38: 1 | R38: 1 | S38: 1 | T38: 1 | U38: 1 | V38: 1 | W38: 1 | X38: 1 | Z38: =+SUM(G38:Y38) -> 17 | AA38: =+Z38*32 -> 544
A39: 31 | B39: IVAN MADARIAGA | C39: KINDER A | F39: LUNCH + MERIENDA /no burger/ panini/keperi/burrito | G39: 1 | H39: 1 | J39: 1 | K39: 1 | L39: 1 | M39: 1 | N39: 1 | O39: 1 | P39: 1 | Q39: 1 | R39: 1 | S39: 1 | T39: 1 | U39: 1 | V39: 1 | W39: 1 | X39: 1 | Z39: =+SUM(G39:Y39) -> 17 | AA39: =+Z39*32 -> 544
A40: 32 | B40: JERRY FLORES LI | C40: KINDER C | Z40: =+SUM(G40:Y40) -> 0 | AA40: =+Z40*32 -> 0
A41: 33 | B41: JHERICK IAN SOLIZ | C41: KINDER B | Z41: =+SUM(G41:Y41) -> 0 | AA41: =+Z41*32 -> 0
A42: 34 | B42: JORGE JIMENEZ | C42: KINDER C | G42: 1 | H42: 1 | J42: 1 | K42: 1 | L42: 1 | M42: 1 | N42: 1 | O42: 1 | P42: 1 | Q42: 1 | R42: 1 | T42: 1 | U42: 1 | V42: 1 | W42: 1 | X42: 1 | Z42: =+SUM(G42:Y42) -> 16 | AA42: =+Z42*32 -> 512
A43: 35 | B43: JOSE CAMILO MAMANI | C43: PRE K A | F43: PAGA FIN DE MES/DEBE 5 DIAS JULIO | G43: 1 | H43: 1 | J43: 1 | K43: 1 | L43: 1 | M43: 1 | N43: 1 | O43: 1 | P43: 1 | Q43: 1 | R43: 1 | S43: 1 | T43: 1 | U43: 1 | V43: 1 | W43: 1 | X43: 1 | Z43: =+SUM(G43:Y43) -> 17 | AA43: =+Z43*32 -> 544
...

Sheet 11;25
A1: HORARIO ESCOLAR 11:25
A5: Nro. | B5: ALUMNO | C5: CURSO | D5: FECHA INICIO | E5: FECHA FIN | F5: OBSERVACIONES | G5: AGOSTO | Z5: PLATOS VENDIDOS | AA5: PLATOS VENDIDOS EN BS
G6: L | H6: M | I6: M | J6: L | K6: M | L6: M | M6: J | N6: V | O6: L | P6: M | Q6: M | R6: J | S6: V | T6: L | U6: M | V6: M | W6: J | X6: V | Y6: L
G7: 1 | H7: 2 | I7: 3 | J7: 4 | K7: 5 | L7: 6 | M7: 7 | N7: 8 | O7: 9 | P7: 10 | Q7: 11 | R7: 12 | S7: 13 | T7: 14 | U7: 15 | V7: 16 | W7: 17 | X7: 18 | Y7: 19
G8: 3 | H8: 4 | I8: 5 | J8: 10 | K8: 11 | L8: 12 | M8: 13 | N8: 14 | O8: 17 | P8: 18 | Q8: 19 | R8: 20 | S8: 21 | T8: 24 | U8: 25 | V8: 26 | W8: 27 | X8: 28 | Y8: 31
A9: 1 | B9: AARON JIMENEZ | C9: 6P | Z9: =+SUM(G9:Y9) -> 0 | AA9: =+Z9*32 -> 0
A10: 2 | B10: ABIGAIL PARADA | C10: 6P | I10: 1 | J10: 1 | Z10: =+SUM(G10:Y10) -> 2 | AA10: =+Z10*32 -> 64
A11: 3 | B11: ABRIL NUÑEZ | C11: 6P | Z11: =+SUM(G11:Y11) -> 0 | AA11: =+Z11*32 -> 0
A12: 4 | B12: ADRIAN SPECHAR | C12: 6P | F12: NO MILANESA | G12: 1 | H12: 1 | I12: 1 | J12: 1 | K12: 1 | L12: 1 | M12: 1 | N12: 1 | O12: 1 | P12: 1 | Q12: 1 | R12: 1 | S12: 1 | T12: 1 | U12: 1 | V12: 1 | W12: 1 | X12: 1 | Z12: =+SUM(G12:Y12) -> 18 | AA12: =+Z12*32 -> 576
A13: 5 | B13: ADRIANA SEAS | C13: 5PA | K13: 1 | L13: 1 | M13: 1 | O13: 1 | P13: 1 | R13: 1 | T13: 1 | V13: 1 | W13: 1 | Z13: =+SUM(G13:Y13) -> 9 | AA13: =+Z13*32 -> 288
A14: 6 | B14: ADRIANO MUÑOZ | C14: 5P | L14: 1 | Z14: =+SUM(G14:Y14) -> 1 | AA14: =+Z14*32 -> 32
A15: 7 | B15: AGUSTIN BARBA | C15: 4P | Z15: =+SUM(G15:Y15) -> 0 | AA15: =+Z15*32 -> 0
A16: 8 | B16: AGUSTIN PEREYRA | C16: 5PB | G16: 1 | H16: 1 | I16: 1 | J16: 1 | K16: 1 | L16: 1 | M16: 1 | N16: 1 | O16: 1 | P16: 1 | Q16: 1 | R16: 1 | S16: 1 | T16: 1 | U16: 1 | V16: 1 | W16: 1 | X16: 1 | Z16: =+SUM(G16:Y16) -> 18 | AA16: =+Z16*32 -> 576
A17: 9 | B17: AGUSTINA SANDOVAL | C17: 4PB | G17: 1 | H17: 1 | I17: 1 | J17: 1 | K17: 1 | L17: 1 | M17: 1 | N17: 1 | O17: 1 | P17: 1 | Q17: 1 | R17: 1 | S17: 1 | T17: 1 | U17: 1 | V17: 1 | W17: 1 | X17: 1 | Z17: =+SUM(G17:Y17) -> 18 | AA17: =+Z17*32 -> 576
A18: 10 | B18: AITANA SARDAN | C18: 5P | G18: 1 | H18: 1 | I18: 1 | K18: 1 | L18: 1 | M18: 1 | N18: 1 | O18: 1 | P18: 1 | Q18: 1 | R18: 1 | T18: 1 | U18: 1 | V18: 1 | X18: 1 | Z18: =+SUM(G18:Y18) -> 15 | AA18: =+Z18*32 -> 480
A19: 11 | B19: ALEXANDER VON BORRIES | C19: 4PB | G19: 1 | H19: 1 | I19: 1 | J19: 1 | K19: 1 | L19: 1 | M19: 1 | N19: 0 | O19: 0 | P19: 1 | Q19: 1 | R19: 1 | S19: 1 | T19: 1 | U19: 1 | V19: 1 | W19: 1 | X19: 1 | Z19: =+SUM(G19:Y19) -> 16 | AA19: =+Z19*32 -> 512
A20: 12 | B20: ALICE RAFAELA NOVILLO | C20: 4PB | W20: 1 | X20: 1 | Z20: =+SUM(G20:Y20) -> 2 | AA20: =+Z20*32 -> 64
A21: 13 | B21: ANDRES AÑEZ | C21: 5PA | F21: TODOS LOS LUNES - AGOSTO TB | G21: 1 | J21: 1 | O21: 1 | R21: 1 | T21: 1 | V21: 1 | W21: 1 | X21: 1 | Z21: =+SUM(G21:Y21) -> 8 | AA21: =+Z21*32 -> 256
A22: 14 | B22: ANIKA MARTINEZ | C22: 5PA | F22: LUNCH + MERIENDA/MENU FIT/HASTA EL 30 DE SEPT | G22: 1 | H22: 1 | I22: 1 | J22: 1 | K22: 1 | L22: 1 | M22: 1 | N22: 1 | O22: 1 | P22: 1 | Q22: 1 | R22: 1 | S22: 1 | T22: 1 | U22: 1 | V22: 1 | W22: 1 | X22: 1 | Z22: =+SUM(G22:Y22) -> 18 | AA22: =+Z22*32 -> 576
A23: 15 | B23: ANITA IRIARTE | C23: 4PB | G23: 1 | J23: 1 | K23: 1 | L23: 1 | P23: 1 | R23: 1 | S23: 1 | T23: 1 | U23: 1 | V23: 1 | W23: 1 | X23: 1 | Z23: =+SUM(G23:Y23) -> 12 | AA23: =+Z23*32 -> 384
A24: 16 | B24: ANTONIA NUMBERG | C24: 4PB | F24: LUNCH + MERIENDA | G24: 1 | H24: 1 | I24: 1 | J24: 1 | K24: 1 | L24: 1 | M24: 1 | N24: 1 | O24: 1 | P24: 1 | Q24: 1 | R24: 1 | S24: 1 | T24: 1 | U24: 1 | V24: 1 | W24: 1 | X24: 1 | Z24: =+SUM(G24:Y24) -> 18 | AA24: =+Z24*32 -> 576
A25: 17 | B25: AMBER MORGAN | C25: 4PA | G25: 1 | H25: 1 | I25: 1 | J25: 1 | K25: 1 | L25: 1 | M25: 1 | N25: 1 | O25: 1 | P25: 1 | Q25: 1 | R25: 1 | S25: 1 | T25: 1 | U25: 1 | V25: 1 | W25: 1 | X25: 1 | Z25: =+SUM(G25:Y25) -> 18 | AA25: =+Z25*32 -> 576
A26: 18 | B26: ALEXIA MORGAN | C26: 6PB | F26: MENU FIT | G26: 1 | H26: 1 | I26: 1 | J26: 1 | K26: 1 | L26: 1 | M26: 1 | N26: 1 | O26: 1 | P26: 1 | Q26: 1 | R26: 1 | S26: 1 | T26: 1 | U26: 1 | V26: 1 | W26: 1 | X26: 1 | Z26: =+SUM(G26:Y26) -> 18 | AA26: =+Z26*32 -> 576
A27: 19 | B27: ALINA ARCE | C27: 4P | Z27: =+SUM(G27:Y27) -> 0 | AA27: =+Z27*32 -> 0
A28: 20 | B28: ANTONELLA LEHM SORIA | C28: 5PB | G28: 1 | H28: 1 | I28: 1 | J28: 1 | K28: 1 | L28: 1 | M28: 1 | N28: 1 | O28: 1 | P28: 1 | Q28: 1 | R28: 1 | S28: 1 | T28: 1 | U28: 1 | V28: 1 | W28: 1 | X28: 1 | Z28: =+SUM(G28:Y28) -> 18 | AA28: =+Z28*32 -> 576
A29: 21 | B29: ARIANA HANDAL | C29: 4PA | N29: 1 | Z29: =+SUM(G29:Y29) -> 1 | AA29: =+Z29*32 -> 32
A30: 22 | B30: ARI SCHAYMAN | C30: 5PA | G30: 1 | H30: 1 | I30: 1 | J30: 1 | K30: 1 | L30: 1 | M30: 1 | N30: 1 | O30: 1 | P30: 1 | Q30: 1 | R30: 1 | S30: 1 | T30: 1 | U30: 1 | V30: 1 | W30: 1 | X30: 1 | Z30: =+SUM(G30:Y30) -> 18 | AA30: =+Z30*32 -> 576
A31: 23 | B31: ARIANA REVILLA | C31: 6PB | Z31: =+SUM(G31:Y31) -> 0 | AA31: =+Z31*32 -> 0
A32: 24 | B32: ARIUS BAUTISTA | C32: 5PB | Z32: =+SUM(G32:Y32) -> 0 | AA32: =+Z32*32 -> 0
A33: 25 | B33: BRUNA ECHART | C33: 4P | J33: 1 | T33: 1 | Z33: =+SUM(G33:Y33) -> 2 | AA33: =+Z33*32 -> 64
A34: 26 | B34: BRUNO VACA PEREIRA | C34: 6PA | F34: LUNES Y VIERNES DE TODO AGOSTO | G34: 1 | J34: 1 | N34: 1 | O34: 1 | S34: 1 | T34: 1 | X34: 1 | Z34: =+SUM(G34:Y34) -> 7 | AA34: =+Z34*32 -> 224
A35: 27 | B35: CAMILA ROCA MANCIA | C35: 4P | I35: 1 | Z35: =+SUM(G35:Y35) -> 1 | AA35: =+Z35*32 -> 32
A36: 28 | B36: CANDY PACHECO | C36: 4P | G36: 1 | H36: 1 | I36: 1 | J36: 1 | K36: 1 | L36: 1 | M36: 1 | N36: 1 | O36: 1 | P36: 1 | Q36: 1 | R36: 1 | S36: 1 | T36: 1 | U36: 1 | V36: 1 | W36: 1 | X36: 1 | Z36: =+SUM(G36:Y36) -> 18 | AA36: =+Z36*32 -> 576
A37: 29 | B37: CATALINA OSTRIA | C37: 4PB | G37: 1 | L37: 1 | O37: 1 | T37: 1 | W37: 1 | Z37: =+SUM(G37:Y37) -> 5 | AA37: =+Z37*32 -> 160
A38: 30 | B38: CATALINA SUAREZ | C38: 5PB | S38: 1 | Z38: =+SUM(G38:Y38) -> 1 | AA38: =+Z38*32 -> 32
A39: 31 | B39: CATARINA ALMEIDA | C39: 4P | G39: 1 | H39: 1 | M39: 1 | N39: 1 | O39: 1 | P39: 1 | Q39: 1 | R39: 1 | S39: 1 | T39: 1 | U39: 1 | V39: 1 | W39: 1 | X39: 1 | Z39: =+SUM(G39:Y39) -> 14 | AA39: =+Z39*32 -> 448
A40: 32 | B40: CARLOS ANDRE AÑEZ | C40: 5P | Z40: =+SUM(G40:Y40) -> 0 | AA40: =+Z40*32 -> 0
A41: 33 | B41: CAYETANA AQUIM | C41: 4P | F41: LUNES/MIERCOLES/VIERNES | G41: 1 | I41: 1 | J41: 1 | L41: 1 | M41: 1 | N41: 1 | O41: 1 | Q41: 1 | S41: 1 | T41: 1 | U41: 1 | V41: 0 | W41: 1 | X41: 1 | Z41: =+SUM(G41:Y41) -> 13 | AA41: =+Z41*32 -> 416
A42: 34 | B42: DAMINA KHOUBBAKHT | C42: 4PB | G42: 1 | H42: 1 | I42: 1 | J42: 1 | K42: 1 | L42: 1 | M42: 1 | N42: 1 | Z42: =+SUM(G42:Y42) -> 8 | AA42: =+Z42*32 -> 256
A43: 35 | B43: DANIEL MENDEZ | C43: 4PB | G43: 1 | J43: 1 | T43: 1 | Z43: =+SUM(G43:Y43) -> 3 | AA43: =+Z43*32 -> 96
...

Sheet 12;00
A1: HORARIO ESCOLAR 12:00
A5: Nro. | B5: ALUMNO | C5: CURSO | D5: FECHA INICIO | E5: FECHA FIN | F5: OBSERVACIONES | G5: AGOSTO | Z5: PLATOS VENDIDOS | AA5: PLATOS VENDIDOS EN BS
G6: L | H6: M | I6: M | J6: L | K6: M | L6: M | M6: J | N6: V | O6: L | P6: M | Q6: M | R6: J | S6: V | T6: L | U6: M | V6: M | W6: J | X6: V | Y6: L
G7: 1 | H7: 2 | I7: 3 | J7: 4 | K7: 5 | L7: 6 | M7: 7 | N7: 8 | O7: 9 | P7: 10 | Q7: 11 | R7: 12 | S7: 13 | T7: 14 | U7: 15 | V7: 16 | W7: 17 | X7: 18 | Y7: 19
G8: 3 | H8: 4 | I8: 5 | J8: 10 | K8: 11 | L8: 12 | M8: 13 | N8: 14 | O8: 17 | P8: 18 | Q8: 19 | R8: 20 | S8: 21 | T8: 24 | U8: 25 | V8: 26 | W8: 27 | X8: 28 | Y8: 31
A9: 1 | B9: ADRI FERRERO | C9: 3P | Z9: =+SUM(G9:Y9) -> 0 | AA9: =+Z9*32 -> 0
A10: 2 | B10: ADRIELYV GONG PACO | C10: 2P | G10: 1 | H10: 1 | I10: 0 | M10: 1 | N10: 0 | O10: 1 | P10: 0 | Q10: 1 | R10: 1 | T10: 1 | W10: 0 | X10: 1 | Z10: =+SUM(G10:Y10) -> 8 | AA10: =+Z10*32 -> 256
A11: 3 | B11: ADRIANA VILLAVICENCIO | C11: 2PB | F11: DEBE MERIENDA | Z11: =+SUM(G11:Y11) -> 0 | AA11: =+Z11*32 -> 0
A12: 4 | B12: AITANA KNEZ | C12: 1P | I12: 1 | X12: 1 | Z12: =+SUM(G12:Y12) -> 2 | AA12: =+Z12*32 -> 64
A13: 5 | B13: AUSTIN HUANG | C13: 3P | Z13: =+SUM(G13:Y13) -> 0 | AA13: =+Z13*32 -> 0
A14: 6 | B14: AGUSTIN SUBIRANA | C14: 3P | F14: FACTURAR | Z14: =+SUM(G14:Y14) -> 0 | AA14: =+Z14*32 -> 0
A15: 7 | B15: AGUSTIN SALINAS | C15: 3P | Z15: =+SUM(G15:Y15) -> 0 | AA15: =+Z15*32 -> 0
A16: 8 | B16: AGUSTIN PINELL | C16: 2PB | Z16: =+SUM(G16:Y16) -> 0 | AA16: =+Z16*32 -> 0
A17: 9 | B17: AUGUSTO NUMBERG | C17: 2PB | F17: ALMUERZO + SNACK/PEDIR COMPROBANTE DE LUNCH | G17: 1 | H17: 1 | I17: 1 | J17: 1 | K17: 1 | L17: 1 | M17: 1 | N17: 1 | O17: 1 | P17: 1 | Q17: 1 | R17: 1 | S17: 1 | T17: 1 | U17: 1 | V17: 1 | W17: 1 | X17: 1 | Z17: =+SUM(G17:Y17) -> 18 | AA17: =+Z17*32 -> 576
A18: 10 | B18: ALHENA TALAMAS | C18: 2PB | Z18: =+SUM(G18:Y18) -> 0 | AA18: =+Z18*32 -> 0
A19: 11 | B19: ALISSA ZACHARIAS MENACHO | C19: 2P | Z19: =+SUM(G19:Y19) -> 0 | AA19: =+Z19*32 -> 0
A20: 12 | B20: ALESSANDRA BARBA | C20: 1P | F20: NO PECETO/NO MAJADITO/NO BURRITO/NO MILA | G20: 1 | H20: 1 | I20: 1 | J20: 1 | K20: 1 | L20: 1 | M20: 1 | N20: 1 | O20: 1 | P20: 1 | Q20: 1 | R20: 1 | S20: 1 | T20: 1 | U20: 1 | V20: 1 | W20: 1 | X20: 1 | Z20: =+SUM(G20:Y20) -> 18 | AA20: =+Z20*32 -> 576
A21: 13 | B21: ALEXANDRA ARNEZ | C21: 1P | Z21: =+SUM(G21:Y21) -> 0 | AA21: =+Z21*32 -> 0
A22: 14 | B22: ALONSO CASTRO | C22: 2P | M22: 1 | Q22: 1 | U22: 1 | Z22: =+SUM(G22:Y22) -> 3 | AA22: =+Z22*32 -> 96
A23: 15 | B23: AlONSO PAZ | C23: 1P | N23: 1 | X23: 1 | Z23: =+SUM(G23:Y23) -> 2 | AA23: =+Z23*32 -> 64
A24: 16 | B24: ALMA ISAIS | C24: 2PB | Z24: =+SUM(G24:Y24) -> 0 | AA24: =+Z24*32 -> 0
A25: 17 | B25: AVRIL NACIF | C25: 1PB | F25: HAMBURGUESA SIN SALSA | G25: 1 | H25: 1 | I25: 1 | J25: 1 | K25: 1 | L25: 1 | M25: 1 | N25: 1 | O25: 1 | P25: 1 | Q25: 1 | T25: 1 | U25: 1 | V25: 1 | W25: 1 | X25: 1 | Z25: =+SUM(G25:Y25) -> 16 | AA25: =+Z25*32 -> 512
A26: 18 | B26: AMANDA CASTEDO | C26: 3PB | Z26: =+SUM(G26:Y26) -> 0 | AA26: =+Z26*32 -> 0
A27: 19 | B27: AMELIA MOLINA | C27: 2P | F27: NO BURRITO | Z27: =+SUM(G27:Y27) -> 0 | AA27: =+Z27*32 -> 0
A28: 20 | B28: ANA CATALINA ASBUN | C28: 3P | Z28: =+SUM(G28:Y28) -> 0 | AA28: =+Z28*32 -> 0
A29: 21 | B29: ANDROS COCHAMADINIS | C29: 1PA | G29: 1 | K29: 1 | O29: 1 | T29: 1 | X29: 1 | Z29: =+SUM(G29:Y29) -> 5 | AA29: =+Z29*32 -> 160
A30: 22 | B30: ANIA CALVO | C30: 1PA | Z30: =+SUM(G30:Y30) -> 0 | AA30: =+Z30*32 -> 0
A31: 23 | B31: ANTONIO DUARTE | C31: 3P | O31: 1 | P31: 1 | Q31: 1 | R31: 1 | S31: 1 | T31: 1 | U31: 1 | V31: 1 | W31: 1 | X31: 1 | Z31: =+SUM(G31:Y31) -> 10 | AA31: =+Z31*32 -> 320
A32: 24 | B32: ANA FABIA SALINAS | C32: 2P | Z32: =+SUM(G32:Y32) -> 0 | AA32: =+Z32*32 -> 0
A33: 25 | B33: BALTAZAR VERGARA | C33: 3P | F33: MENU FIT - SOLO FRUTA DE POSTRE | G33: 1 | H33: 1 | I33: 1 | J33: 1 | K33: 1 | L33: 1 | M33: 1 | N33: 1 | O33: 1 | P33: 1 | Q33: 1 | R33: 1 | S33: 1 | T33: 1 | U33: 1 | V33: 1 | W33: 1 | X33: 1 | Z33: =+SUM(G33:Y33) -> 18 | AA33: =+Z33*32 -> 576
A34: 26 | B34: BARRETT CHESHIER | C34: 3P | G34: 1 | H34: 1 | I34: 1 | J34: 1 | K34: 1 | L34: 1 | M34: 1 | N34: 1 | O34: 1 | P34: 1 | Q34: 1 | R34: 1 | S34: 1 | T34: 1 | U34: 1 | V34: 1 | W34: 1 | X34: 1 | Z34: =+SUM(G34:Y34) -> 18 | AA34: =+Z34*32 -> 576
A35: 27 | B35: BENJAMIN HANDAL | C35: 1PB | N35: 1 | Z35: =+SUM(G35:Y35) -> 1 | AA35: =+Z35*32 -> 32
A36: 28 | B36: BENJAMI LUPO | C36: 2P | Z36: =+SUM(G36:Y36) -> 0 | AA36: =+Z36*32 -> 0
A37: 29 | B37: BLANCA GIRONAS | C37: 3P | Z37: =+SUM(G37:Y37) -> 0 | AA37: =+Z37*32 -> 0
A38: 30 | B38: BRADLEY MORGAN | C38: 2P | G38: 1 | H38: 1 | I38: 1 | J38: 1 | K38: 1 | L38: 1 | M38: 1 | N38: 1 | O38: 1 | P38: 1 | Q38: 1 | R38: 1 | S38: 1 | T38: 1 | U38: 1 | V38: 1 | W38: 1 | X38: 1 | Z38: =+SUM(G38:Y38) -> 18 | AA38: =+Z38*32 -> 576
A39: 31 | B39: CARLOTA RIBA | C39: 3PB | F39: NO BURRITO | G39: 1 | H39: 1 | I39: 1 | J39: 1 | K39: 1 | L39: 1 | M39: 1 | N39: 1 | O39: 1 | P39: 1 | Q39: 1 | R39: 1 | S39: 1 | T39: 1 | U39: 1 | V39: 0 | W39: 1 | X39: 1 | Z39: =+SUM(G39:Y39) -> 17 | AA39: =+Z39*32 -> 544
A40: 32 | B40: CATALINA ASBUN | C40: 3P | Z40: =+SUM(G40:Y40) -> 0 | AA40: =+Z40*32 -> 0
A41: 33 | B41: CATALINA LEYTON | C41: 1P | J41: 1 | M41: 1 | Z41: =+SUM(G41:Y41) -> 2 | AA41: =+Z41*32 -> 64
A42: 34 | B42: CATALINA SALAZAR | C42: 2P | G42: 1 | H42: 1 | I42: 1 | J42: 1 | K42: 1 | M42: 1 | N42: 1 | O42: 1 | P42: 1 | Q42: 1 | R42: 1 | S42: 1 | T42: 1 | U42: 1 | V42: 1 | W42: 1 | X42: 1 | Z42: =+SUM(G42:Y42) -> 17 | AA42: =+Z42*32 -> 544
A43: 35 | B43: CAMILA SPECHAR | C43: 2P | F43: NO KEPERÍ/NO MAJADITO/NO PANINI | G43: 1 | H43: 1 | I43: 1 | J43: 1 | K43: 1 | L43: 1 | M43: 1 | N43: 1 | O43: 1 | P43: 1 | Q43: 1 | R43: 1 | S43: 1 | T43: 1 | U43: 1 | V43: 1 | W43: 1 | X43: 1 | Z43: =+SUM(G43:Y43) -> 18 | AA43: =+Z43*32 -> 576
...

Sheet 12;40
A1: HORARIO ESCOLAR 12:40
A5: Nro | B5: ALUMNO | C5: CURSO | D5: FECHA INICIO | E5: FECHA FIN | F5: OBSERVACIONES | G5: AGOSTO | Z5: PLATOS VENDIDOS | AA5: PLATOS VENDIDOS EN BS
G6: L | H6: M | I6: M | J6: L | K6: M | L6: M | M6: J | N6: V | O6: L | P6: M | Q6: M | R6: J | S6: V | T6: L | U6: M | V6: M | W6: J | X6: V | Y6: L
G7: 1 | H7: 2 | I7: 3 | J7: 4 | K7: 5 | L7: 6 | M7: 7 | N7: 8 | O7: 9 | P7: 10 | Q7: 11 | R7: 12 | S7: 13 | T7: 14 | U7: 15 | V7: 16 | W7: 17 | X7: 18 | Y7: 19
G8: 3 | H8: 4 | I8: 5 | J8: 10 | K8: 11 | L8: 12 | M8: 13 | N8: 14 | O8: 17 | P8: 18 | Q8: 19 | R8: 20 | S8: 21 | T8: 24 | U8: 25 | V8: 26 | W8: 27 | X8: 28 | Y8: 31
A9: 1 | B9: ALDO FORTI | C9: 2S | G9: 1 | H9: 1 | J9: 1 | K9: 1 | L9: 1 | M9: 1 | N9: 1 | O9: 1 | P9: 1 | Q9: 1 | R9: 1 | S9: 1 | T9: 1 | U9: 1 | V9: 1 | W9: 1 | X9: 1 | Z9: =+SUM(G9:Y9) -> 17 | AA9: =+Z9*35 -> 595
A10: 2 | B10: ALONSO VIERA | C10: 1S | G10: 1 | J10: 1 | O10: 1 | T10: 1 | Z10: =+SUM(G10:Y10) -> 4 | AA10: =+Z10*35 -> 140
A11: 3 | B11: AARON JUSTINIANO | C11: 1S | G11: 1 | H11: 1 | J11: 1 | K11: 1 | L11: 1 | M11: 1 | N11: 1 | O11: 1 | P11: 1 | Q11: 1 | R11: 1 | S11: 1 | T11: 1 | U11: 1 | V11: 1 | W11: 1 | X11: 1 | Z11: =+SUM(G11:Y11) -> 17 | AA11: =+Z11*35 -> 595
A12: 4 | B12: ALDANA PEREDO | C12: 1S | G12: 1 | N12: 1 | V12: 1 | Z12: =+SUM(G12:Y12) -> 3 | AA12: =+Z12*35 -> 105
A13: 5 | B13: ALVARO RODRIGUEZ EZEQUIEL | C13: 1S | Q13: 1 | Z13: =+SUM(G13:Y13) -> 1 | AA13: =+Z13*35 -> 35
A14: 6 | B14: AMANDA CIRBIAN | C14: 1S | Z14: =+SUM(G14:Y14) -> 0 | AA14: =+Z14*35 -> 0
A15: 7 | B15: AMANDA CANTIN | C15: 1S | J15: 1 | K15: 1 | L15: 1 | M15: 1 | N15: 1 | O15: 1 | P15: 1 | Q15: 1 | R15: 1 | S15: 1 | T15: 1 | U15: 1 | V15: 1 | W15: 1 | X15: 1 | Z15: =+SUM(G15:Y15) -> 15 | AA15: =+Z15*35 -> 525
A16: 8 | B16: AMANDA VALLE | C16: 1S | H16: 1 | J16: 1 | L16: 1 | O16: 1 | R16: 1 | Z16: =+SUM(G16:Y16) -> 5 | AA16: =+Z16*35 -> 175
A17: 9 | B17: ANA LUCIA QUINTELA | C17: 6S | T17: 1 | Z17: =+SUM(G17:Y17) -> 1 | AA17: =+Z17*35 -> 35
A18: 10 | B18: ANA FABIA PARADA | C18: 1S | G18: 1 | J18: 1 | N18: 1 | O18: 1 | Z18: =+SUM(G18:Y18) -> 4 | AA18: =+Z18*35 -> 140
A19: 11 | B19: ANA MARIA ARROYAVE | C19: 1S | F19: FACTURAR | G19: 1 | K19: 1 | P19: 1 | Q19: 1 | Z19: =+SUM(G19:Y19) -> 4 | AA19: =+Z19*35 -> 140
A20: 12 | B20: ANA SOFIA NARVAEZ | C20: 1S | T20: 1 | Z20: =+SUM(G20:Y20) -> 1 | AA20: =+Z20*35 -> 35
A21: 13 | B21: ANDRES RICO | C21: 1S | Z21: =+SUM(G21:Y21) -> 0 | AA21: =+Z21*35 -> 0
A22: 14 | B22: ADRIAN TERCEROS | C22: 6S | O22: 1
A23: 15 | B23: AGUSTINA REVILLA | C23: 6S | Z23: =+SUM(G23:Y23) -> 0 | AA23: =+Z23*35 -> 0
A24: 16 | B24: AGUSTINA VALENCIA | C24: 2S | G24: 1 | H24: 1 | J24: 1 | K24: 1 | L24: 1 | M24: 1 | N24: 1 | O24: 1 | P24: 1 | Q24: 1 | R24: 1 | S24: 1 | T24: 1 | U24: 1 | V24: 1 | W24: 1 | X24: 1 | Z24: =+SUM(G24:Y24) -> 17 | AA24: =+Z24*35 -> 595
A25: 17 | B25: ALICIA LINALE | C25: 2S | G25: 1 | J25: 1 | L25: 1 | N25: 1 | O25: 1 | X25: 1 | Z25: =+SUM(G25:Y25) -> 6 | AA25: =+Z25*35 -> 210
A26: 18 | B26: ALIYAH CESPEDES | C26: 6S | H26: 1 | L26: 1 | M26: 1 | O26: 1 | R26: 1 | T26: 1 | Z26: =+SUM(G26:Y26) -> 6 | AA26: =+Z26*35 -> 210
A27: 19 | B27: ALEXIA QUIROGA | C27: 6S | F27: MENU FIT | G27: 1 | H27: 1 | J27: 1 | K27: 1 | L27: 1 | M27: 1 | N27: 1 | O27: 1 | P27: 1 | Q27: 1 | R27: 1 | S27: 1 | T27: 1 | U27: 1 | V27: 1 | W27: 1 | X27: 1 | Z27: =+SUM(G27:Y27) -> 17 | AA27: =+Z27*35 -> 595
A28: 20 | B28: ANTONIO SORIA | C28: 6S | G28: 1 | J28: 1 | M28: 1 | S28: 1 | Z28: =+SUM(G28:Y28) -> 4 | AA28: =+Z28*35 -> 140
A29: 21 | B29: ARIANA RIVAS | C29: 1S | Z29: =+SUM(G29:Y29) -> 0 | AA29: =+Z29*35 -> 0
A30: 22 | B30: AZUL MARTINEZ | C30: 2SA | Z30: =+SUM(G30:Y30) -> 0 | AA30: =+Z30*35 -> 0
A31: 23 | B31: BENJAMIN RIVERO | C31: 1S | Z31: =+SUM(G31:Y31) -> 0 | AA31: =+Z31*35 -> 0
A32: 24 | B32: BRUNO COMPANY | C32: 2S | Z32: =+SUM(G32:Y32) -> 0 | AA32: =+Z32*35 -> 0
A33: 25 | B33: BRUNO PATIÑO | C33: 1S | F33: DEBE 5 DIAS DE JULIO | G33: 1 | H33: 1 | J33: 0 | K33: 0 | L33: 1 | M33: 0 | N33: 0 | O33: 0 | P33: 1 | Q33: 0 | R33: 1 | S33: 1 | T33: 1 | U33: 1 | V33: 1 | W33: 0 | X33: 1 | Z33: =+SUM(G33:Y33) -> 10 | AA33: =+Z33*35 -> 350
A34: 26 | B34: BRUNA GUTIERREZ | C34: 1S | G34: 1 | K34: 1 | M34: 1 | O34: 1 | T34: 1 | Z34: =+SUM(G34:Y34) -> 5 | AA34: =+Z34*35 -> 175
A35: 27 | B35: CAMILA KIARA MAMANI | C35: 1S | F35: ENVIAR QR/MENU FIT/DEBE 5 DIAS D JULIO | G35: 1 | H35: 1 | J35: 1 | K35: 1 | L35: 1 | M35: 1 | N35: 1 | O35: 1 | P35: 1 | Q35: 1 | R35: 1 | S35: 1 | T35: 1 | U35: 1 | V35: 1 | W35: 1 | X35: 1 | Z35: =+SUM(G35:Y35) -> 17 | AA35: =+Z35*35 -> 595
A36: 28 | B36: CAMILA CADARIO | C36: 6S | G36: 1 | H36: 1 | J36: 1 | K36: 1 | M36: 1 | O36: 1 | P36: 1 | Q36: 1 | T36: 1 | U36: 1 | V36: 1 | W36: 1 | X36: 1 | Z36: =+SUM(G36:Y36) -> 13 | AA36: =+Z36*35 -> 455
A37: 29 | B37: CAMILA RODRIGUEZ | C37: 6S | Z37: =+SUM(G37:Y37) -> 0 | AA37: =+Z37*35 -> 0
A38: 30 | B38: CAMILA ROSALES | C38: 6S | F38: FACTURAR | G38: 1 | H38: 1 | J38: 1 | K38: 1 | L38: 1 | M38: 1 | N38: 1 | O38: 1 | P38: 1 | Q38: 1 | R38: 1 | S38: 1 | T38: 1 | U38: 1 | V38: 1 | W38: 1 | X38: 1 | Z38: =+SUM(G38:Y38) -> 17 | AA38: =+Z38*35 -> 595
A39: 31 | B39: CATALINA MORALES | C39: 6S | F39: MENU FIT | G39: 1 | H39: 1 | J39: 1 | K39: 1 | L39: 1 | M39: 1 | N39: 1 | O39: 1 | P39: 1 | U39: 1 | V39: 1 | W39: 1 | X39: 1 | Z39: =+SUM(G39:Y39) -> 13 | AA39: =+Z39*35 -> 455
A40: 32 | B40: CHLOE DEDROOG | C40: 2S | Z40: =+SUM(G40:Y40) -> 0 | AA40: =+Z40*35 -> 0
A41: 33 | B41: CRISTOPHER VON BORRIES | C41: 1S | G41: 1 | H41: 1 | J41: 1 | K41: 1 | L41: 1 | M41: 1 | N41: 1 | O41: 1 | P41: 1 | Q41: 1 | R41: 1 | S41: 1 | T41: 1 | U41: 1 | V41: 1 | W41: 1 | X41: 1 | Z41: =+SUM(G41:Y41) -> 17 | AA41: =+Z41*35 -> 595
A42: 34 | B42: DAMOON KHOUBBAKHT | C42: 1SB | G42: 1 | H42: 1 | J42: 1 | K42: 1 | L42: 1 | M42: 1 | N42: 1 | Z42: =+SUM(G42:Y42) -> 7 | AA42: =+Z42*35 -> 245
A43: 35 | B43: DARIO GUTIERREZ | C43: 2S | G43: 1 | H43: 1 | J43: 1 | K43: 1 | L43: 1 | M43: 1 | N43: 1 | O43: 1 | P43: 1 | Q43: 1 | R43: 1 | S43: 1 | T43: 1 | U43: 1 | V43: 1 | W43: 1 | X43: 1 | Z43: =+SUM(G43:Y43) -> 17 | AA43: =+Z43*35 -> 595
...

Sheet 13;05
A1: HORARIO ESCOLAR 13:05
A5: Nro. | B5: ALUMNO | C5: CURSO | D5: FECHA INICIO | E5: FECHA FIN | F5: OBSERVACIONES | G5: AGOSTO | Z5: PLATOS VENDIDOS | AA5: PLATOS VENDIDOS EN BS
G6: L | H6: M | I6: M | J6: L | K6: M | L6: M | M6: J | N6: V | O6: L | P6: M | Q6: M | R6: J | S6: V | T6: L | U6: M | V6: M | W6: J | X6: V | Y6: L
G7: 1 | H7: 2 | I7: 3 | J7: 4 | K7: 5 | L7: 6 | M7: 7 | N7: 8 | O7: 9 | P7: 10 | Q7: 11 | R7: 12 | S7: 13 | T7: 14 | U7: 15 | V7: 16 | W7: 17 | X7: 18 | Y7: 19
G8: 3 | H8: 4 | I8: 5 | J8: 10 | K8: 11 | L8: 12 | M8: 13 | N8: 14 | O8: 17 | P8: 18 | Q8: 19 | R8: 20 | S8: 21 | T8: 24 | U8: 25 | V8: 26 | W8: 27 | X8: 28 | Y8: 31
A9: 1 | B9: ADANAE ARCE | C9: 3S | G9: 1 | H9: 1 | J9: 1 | K9: 1 | L9: 1 | M9: 1 | N9: 1 | O9: 1 | P9: 1 | Q9: 1 | R9: 1 | S9: 1 | T9: 1 | U9: 1 | V9: 1 | W9: 1 | X9: 1 | Z9: =+SUM(G9:Y9) -> 17 | AA9: =+Z9*35 -> 595
A10: 2 | B10: AGUSTIN BRÜCKNER | C10: 3S | G10: 1 | H10: 1 | J10: 1 | K10: 1 | L10: 1 | M10: 1 | N10: 1 | O10: 1 | P10: 1 | Q10: 1 | R10: 1 | S10: 1 | T10: 1 | U10: 1 | V10: 1 | W10: 1 | X10: 1 | Z10: =+SUM(G10:Y10) -> 17 | AA10: =+Z10*35 -> 595
A11: 3 | B11: AGUSTINA PATIÑO | C11: 3S | F11: MENU FIT | G11: 1 | H11: 1 | J11: 1 | M11: 1 | N11: 1 | T11: 1 | U11: 1 | V11: 1 | W11: 1 | X11: 1 | Z11: =+SUM(G11:Y11) -> 10 | AA11: =+Z11*35 -> 350
A12: 4 | B12: ALAIN NUÑEZ | C12: 3S | G12: 1 | H12: 1 | J12: 1 | K12: 1 | L12: 1 | M12: 1 | N12: 1 | O12: 1 | P12: 1 | Q12: 1 | R12: 1 | S12: 1 | T12: 1 | U12: 1 | V12: 1 | W12: 1 | X12: 1 | Z12: =+SUM(G12:Y12) -> 17 | AA12: =+Z12*35 -> 595
A13: 5 | B13: ALVARO REVILLA | C13: 5S | G13: 1 | H13: 1 | K13: 1 | L13: 1 | M13: 1 | N13: 1 | O13: 1 | P13: 1 | Q13: 1 | R13: 1 | T13: 1 | V13: 1 | X13: 1 | Z13: =+SUM(G13:Y13) -> 13 | AA13: =+Z13*35 -> 455
A14: 6 | B14: ALEXIA RIBERA | C14: 4S | F14: MENU FIT | G14: 1 | H14: 1 | J14: 1 | K14: 1 | L14: 1 | M14: 1 | N14: 1 | O14: 1 | P14: 1 | Q14: 1 | R14: 1 | S14: 1 | T14: 1 | U14: 1 | V14: 1 | W14: 1 | X14: 1 | Z14: =+SUM(G14:Y14) -> 17 | AA14: =+Z14*35 -> 595
A15: 7 | B15: ALEJANDRO QUIROGA | C15: 5S | Z15: =+SUM(G15:Y15) -> 0 | AA15: =+Z15*35 -> 0
A16: 8 | B16: ANDERE KNEZ | C16: 4S | Z16: =+SUM(G16:Y16) -> 0 | AA16: =+Z16*35 -> 0
A17: 9 | B17: ANIA ARAUZ | C17: 4S | Z17: =+SUM(G17:Y17) -> 0 | AA17: =+Z17*35 -> 0
A18: 10 | B18: ANIK PETERSEN | C18: 4S | F18: DEBE 2 ALMUERZOS | Z18: =+SUM(G18:Y18) -> 0 | AA18: =+Z18*35 -> 0
A19: 11 | B19: ANDRES GALDOS | C19: 4S | Z19: =+SUM(G19:Y19) -> 0 | AA19: =+Z19*35 -> 0
A20: 12 | B20: ANDRES BRUCKNER | C20: 3SB | H20: 1 | M20: 1 | N20: 1 | P20: 1 | R20: 1 | S20: 1 | U20: 1 | W20: 1 | X20: 1 | Z20: =+SUM(G20:Y20) -> 9 | AA20: =+Z20*35 -> 315
A21: 13 | B21: ANDRES PARADA | C21: 5S | Z21: =+SUM(G21:Y21) -> 0 | AA21: =+Z21*35 -> 0
A22: 14 | B22: ANGELINA MENDOZA | C22: 4S | Z22: =+SUM(G22:Y22) -> 0 | AA22: =+Z22*35 -> 0
A23: 15 | B23: BASTIAN GARECA | C23: 5S | Z23: =+SUM(G23:Y23) -> 0 | AA23: =+Z23*35 -> 0
A24: 16 | B24: BENEDETTA GIANINI | C24: 3SB | F24: MENU FIT | H24: 1 | J24: 1 | K24: 1 | L24: 1 | M24: 0 | N24: 1 | O24: 1 | P24: 1 | Q24: 1 | R24: 1 | S24: 1 | U24: 1 | W24: 1 | X24: 1 | Z24: =+SUM(G24:Y24) -> 13 | AA24: =+Z24*35 -> 455
A25: 17 | B25: BRUNA MEDINA | C25: 3SA | G25: 1 | H25: 1 | J25: 1 | K25: 1 | L25: 1 | M25: 1 | N25: 1 | O25: 1 | P25: 1 | Q25: 1 | R25: 1 | S25: 1 | T25: 1 | U25: 1 | V25: 1 | W25: 1 | X25: 1 | Z25: =+SUM(G25:Y25) -> 17 | AA25: =+Z25*35 -> 595
A26: 18 | B26: BRUNO REVILLA | C26: 3SA | Z26: =+SUM(G26:Y26) -> 0 | AA26: =+Z26*35 -> 0
A27: 19 | B27: BRUNA VALDEZ | C27: 5S | F27: NO LASAGNA | G27: 1 | H27: 1 | J27: 1 | K27: 1 | L27: 1 | M27: 1 | N27: 1 | O27: 1 | T27: 1 | U27: 1 | V27: 1 | W27: 1 | X27: 1 | Z27: =+SUM(G27:Y27) -> 13 | AA27: =+Z27*35 -> 455
A28: 20 | B28: CAROLINA CUELLAR | C28: 5S | F28: FACTURAR | G28: 1 | H28: 1 | J28: 1 | K28: 1 | L28: 1 | M28: 1 | N28: 1 | O28: 1 | P28: 1 | Q28: 1 | R28: 0 | S28: 1 | T28: 1 | U28: 1 | V28: 1 | W28: 1 | X28: 1 | Z28: =+SUM(G28:Y28) -> 16 | AA28: =+Z28*35 -> 560
A29: 21 | B29: CAROLINA DEL SOLAR | C29: 5S | F29: TODOS LOS LUNES | Z29: =+SUM(G29:Y29) -> 0 | AA29: =+Z29*35 -> 0
A30: 22 | B30: CARLOS PABLO MONTERO | C30: 5S | F30: INTERCALAR PECHUGA Y BIFE | G30: 1 | J30: 1 | K30: 1 | L30: 1 | M30: 1 | N30: 1 | O30: 1 | P30: 1 | Q30: 1 | R30: 1 | S30: 1 | T30: 1 | U30: 1 | V30: 1 | W30: 1 | X30: 1 | Z30: =+SUM(G30:Y30) -> 16 | AA30: =+Z30*35 -> 560
A31: 23 | B31: CATALINA PATIÑO | C31: 5S | G31: 1 | H31: 1 | J31: 1 | Z31: =+SUM(G31:Y31) -> 3 | AA31: =+Z31*35 -> 105
A32: 24 | B32: DANIEL KHOUBBAKHT | C32: 3SA | G32: 1 | H32: 1 | J32: 1 | K32: 1 | L32: 1 | M32: 1 | N32: 1 | Z32: =+SUM(G32:Y32) -> 7 | AA32: =+Z32*35 -> 245
A33: 25 | B33: DASHA MORALES | C33: 4S | F33: MENU FIT | G33: 1 | H33: 1 | J33: 1 | K33: 1 | L33: 1 | M33: 1 | N33: 1 | O33: 1 | P33: 1 | Q33: 1 | R33: 1 | S33: 1 | T33: 1 | U33: 1 | V33: 1 | W33: 1 | X33: 1 | Z33: =+SUM(G33:Y33) -> 17 | AA33: =+Z33*35 -> 595
A34: 26 | B34: DELFINA VACARREZA | C34: 4S | Z34: =+SUM(G34:Y34) -> 0 | AA34: =+Z34*35 -> 0
A35: 27 | B35: DIEGO ROCA | C35: 3SB | G35: 1 | H35: 1 | J35: 1 | L35: 1 | P35: 1 | Q35: 1 | S35: 1 | T35: 1 | U35: 1 | V35: 1 | X35: 1 | Z35: =+SUM(G35:Y35) -> 11 | AA35: =+Z35*35 -> 385
A36: 28 | B36: DOMINIQUE ARRUE | C36: 5S | F36: MENU FIT | G36: 1 | H36: 1 | J36: 1 | K36: 1 | L36: 1 | M36: 1 | N36: 1 | O36: 1 | P36: 1 | Q36: 1 | R36: 1 | S36: 1 | T36: 1 | U36: 1 | V36: 1 | W36: 1 | X36: 1 | Z36: =+SUM(G36:Y36) -> 17 | AA36: =+Z36*35 -> 595
A37: 29 | B37: EMMA GARAFULIUC | C37: 3S | Z37: =+SUM(G37:Y37) -> 0 | AA37: =+Z37*35 -> 0
A38: 30 | B38: EMILIO FORTI | C38: 4S | Z38: =+SUM(G38:Y38) -> 0 | AA38: =+Z38*35 -> 0
A39: 31 | B39: ESTEBAN RODRIGUEZ | C39: 4S | G39: 1 | J39: 1 | O39: 1 | P39: 1 | Q39: 1 | T39: 1 | V39: 1 | W39: 1 | Z39: =+SUM(G39:Y39) -> 8 | AA39: =+Z39*35 -> 280
A40: 32 | B40: FELIPE MORALES | C40: 4S | G40: 1 | H40: 1 | J40: 1 | K40: 1 | L40: 1 | M40: 1 | N40: 1 | O40: 1 | P40: 1 | Q40: 1 | R40: 1 | U40: 1 | V40: 1 | W40: 1 | X40: 1 | Z40: =+SUM(G40:Y40) -> 15 | AA40: =+Z40*35 -> 525
A41: 33 | B41: FERNANDO BERRANACHEA | C41: 5S | G41: 1 | H41: 1 | J41: 1 | M41: 1 | O41: 1 | S41: 1 | Z41: =+SUM(G41:Y41) -> 6 | AA41: =+Z41*35 -> 210
A42: 34 | B42: FIORELLA VISCARRA | C42: 3S | G42: 1 | H42: 1 | J42: 1 | K42: 1 | L42: 1 | M42: 1 | N42: 1 | O42: 1 | P42: 1 | Q42: 1 | R42: 1 | S42: 1 | T42: 1 | U42: 1 | V42: 1 | W42: 1 | X42: 1 | Z42: =+SUM(G42:Y42) -> 17 | AA42: =+Z42*35 -> 595
A43: 35 | B43: FLORENCIA VISCARRA | C43: 5S | F43: NO PASTAS/CAMBIAR A MENU FIT | G43: 1 | H43: 1 | J43: 1 | K43: 1 | L43: 1 | M43: 1 | N43: 1 | O43: 1 | P43: 1 | Q43: 1 | R43: 1 | S43: 1 | T43: 1 | U43: 1 | V43: 1 | W43: 1 | X43: 1 | Z43: =+SUM(G43:Y43) -> 17 | AA43: =+Z43*35 -> 595
...

Sheet RESUMEN 20 AL 24
D1: PERIODO DE CERTIFICACION CON EL COLEGIO "SCIS" DEL 20 AL 24 DE JULIO
A5: DETALLE TURNO | C5: 46223 | D5: 46224 | E5: 46225 | F5: 46226 | G5: 46227 | H5: TOTAL PLATOS VENDIDOS | I5: PRECIO UNITARIO BS | J5: PRECIO TOTAL BS.
A7: TURNO 1 | B7: 0.49305556 | C7: =+'11;50'!#REF! -> #REF! | D7: =+'11;50'!#REF! -> #REF! | E7: =+'11;50'!#REF! -> #REF! | F7: =+'11;50'!#REF! -> #REF! | G7: =+'11;50'!#REF! -> #REF! | H7: =SUM(C7:G7) -> #REF! | I7: 32 | J7: `
A8: TURNO 2 | B8: 0.5 | C8: =+'12;00'!#REF! -> #REF! | D8: =+'12;00'!#REF! -> #REF! | E8: =+'12;00'!#REF! -> #REF! | F8: =+'12;00'!#REF! -> #REF! | G8: =+'12;00'!#REF! -> #REF! | H8: =SUM(C8:G8) -> #REF! | I8: 32 | J8: =+H8*I8 -> #REF!
A9: TURNO 3 | B9: 0.47569444 | C9: =+'11;25'!#REF! -> #REF! | D9: =+'11;25'!#REF! -> #REF! | E9: =+'11;25'!#REF! -> #REF! | F9: =+'11;25'!#REF! -> #REF! | G9: =+'11;25'!#REF! -> #REF! | H9: =SUM(C9:G9) -> #REF! | I9: 32 | J9: =+H9*I9 -> #REF!
A10: TURNO 4 | B10: 0.52777778 | C10: =+'12;40'!#REF! -> #REF! | D10: =+'12;40'!#REF! -> #REF! | E10: =+'12;40'!#REF! -> #REF! | F10: =+'12;40'!#REF! -> #REF! | G10: =+'12;40'!#REF! -> #REF! | H10: =SUM(C10:G10) -> #REF! | I10: 35 | J10: =+H10*I10 -> #REF!
A11: TURNO 5 | B11: 0.54513889 | C11: =+'13;05'!#REF! -> #REF! | D11: =+'13;05'!#REF! -> #REF! | E11: =+'13;05'!#REF! -> #REF! | F11: =+'13;05'!#REF! -> #REF! | G11: =+'13;05'!#REF! -> #REF! | H11: =SUM(C11:G11) -> #REF! | I11: 35 | J11: =+H11*I11 -> #REF!
A12: TOTALES | C12: =SUM(C7:C11) -> #REF! | D12: =SUM(D7:D11) -> #REF! | E12: =SUM(E7:E11) -> #REF! | F12: =SUM(F7:F11) -> #REF! | G12: =SUM(G7:G11) -> #REF! | H12: =SUM(H7:H11) -> #REF!
H13: =SUM(H7:H11) -> #REF! | I13: BOLIVIANOS | J13: =SUM(J7:J11) -> #REF!

Sheet RES 03 AL 05
D1: PERIODO DE CERTIFICACION CON EL COLEGIO "SCIS" DEL 03 AL 05 DE AGOSTO DE 2026
A5: DETALLE TURNO | C5: 46237 | D5: 46238 | E5: 46239 | F5: 46240 | G5: 46241 | H5: TOTAL PLATOS VENDIDOS | I5: IMPORTE POR PLATO BS. | J5: IMPORTE TOTAL A PAGAR BS.
A7: TURNO 1 | B7: 0.49305556 | C7: =+'11;50'!G95 -> 35 | D7: =+'11;50'!H95 -> 34 | E7: =+'11;50'!I95 -> 0 | H7: =SUM(C7:G7) -> 69 | I7: 32 | J7: =+H7*I7 -> 2208
A8: TURNO 2 | B8: 0.5 | C8: =+'12;00'!G158 -> 62 | D8: =+'12;00'!H158 -> 56 | E8: =+'12;00'!I158 -> 59 | H8: =SUM(C8:G8) -> 177 | I8: 32 | J8: =+H8*I8 -> 5664
A9: TURNO 3 | B9: 0.47569444 | C9: =+'11;25'!G160 -> 65 | D9: =+'11;25'!H160 -> 52 | E9: =+'11;25'!I160 -> 57 | H9: =SUM(C9:G9) -> 174 | I9: 32 | J9: =+H9*I9 -> 5568
A10: TURNO 4 | B10: 0.52777778 | C10: =+'12;40'!G155 -> 70 | D10: =+'12;40'!H155 -> 59 | E10: =+'12;40'!I155 -> 1 | H10: =SUM(C10:G10) -> 130 | I10: 35 | J10: =+H10*I10 -> 4550
A11: TURNO 5 | B11: 0.54513889 | C11: =+'13;05'!G156 -> 60 | D11: =+'13;05'!H156 -> 54 | E11: =+'13;05'!I156 -> 0 | H11: =SUM(C11:G11) -> 114 | I11: 35 | J11: =+H11*I11 -> 3990
A12: TOTALES | C12: =SUM(C7:C11) -> 292 | D12: =SUM(D7:D11) -> 255 | E12: =SUM(E7:E11) -> 117 | F12: =SUM(F7:F11) -> 0 | G12: =SUM(G7:G11) -> 0 | I12: 0 | J12: =+H12*I12 -> 0
F13: CANTIDAD | H13: =SUM(H7:H11) -> 664 | I13: BOLIVIANOS | J13: =SUM(J7:J11) -> 21980

Sheet RES 10 AL 14
D1: PERIODO DE CERTIFICACION CON EL COLEGIO "SCIS" DEL 10 AL 14 DE AGOSTO DE 2026
A5: DETALLE TURNO | C5: 46244 | D5: 46245 | E5: 46246 | F5: 46247 | G5: 46248 | H5: TOTAL PLATOS VENDIDOS | I5: IMPORTE POR PLATO BS. | J5: IMPORTE TOTAL A PAGAR BS.
A7: TURNO 1 | B7: 0.49305556 | C7: =+'11;50'!J95 -> 35 | D7: =+'11;50'!K95 -> 35 | E7: =+'11;50'!L95 -> 33 | F7: =+'11;50'!M95 -> 34 | G7: =+'11;50'!N95 -> 32 | H7: =SUM(C7:G7) -> 169 | I7: 32 | J7: =+I7*H7 -> 5408
A8: TURNO 2 | B8: 0.5 | C8: =+'12;00'!J158 -> 59 | D8: =+'12;00'!K158 -> 53 | E8: =+'12;00'!L158 -> 55 | F8: =+'12;00'!M158 -> 54 | G8: =+'12;00'!N158 -> 58 | H8: =SUM(C8:G8) -> 279 | I8: 32 | J8: =+I8*H8 -> 8928
A9: TURNO 3 | B9: 0.47569444 | C9: =+'11;25'!J160 -> 64 | D9: =+'11;25'!K160 -> 55 | E9: =+'11;25'!L160 -> 57 | F9: =+'11;25'!M160 -> 58 | G9: =+'11;25'!N160 -> 58 | H9: =SUM(C9:G9) -> 292 | I9: 32 | J9: =+I9*H9 -> 9344
A10: TURNO 4 | B10: 0.52777778 | C10: =+'12;40'!J155 -> 65 | D10: =+'12;40'!K155 -> 58 | E10: =+'12;40'!L155 -> 57 | F10: =+'12;40'!M155 -> 57 | G10: =+'12;40'!N155 -> 57 | H10: =SUM(C10:G10) -> 294 | I10: 35 | J10: =+I10*H10 -> 10290
A11: TURNO 5 | B11: 0.54513889 | C11: =+'13;05'!J156 -> 56 | D11: =+'13;05'!K156 -> 52 | E11: =+'13;05'!L156 -> 50 | F11: =+'13;05'!M156 -> 52 | G11: =+'13;05'!N156 -> 53 | H11: =SUM(C11:G11) -> 263 | I11: 35 | J11: =+I11*H11 -> 9205
A12: TOTALES | C12: =+SUM(C7:C11) -> 279 | D12: =+SUM(D7:D11) -> 253 | E12: =+SUM(E7:E11) -> 252 | F12: =+SUM(F7:F11) -> 255 | G12: =+SUM(G7:G11) -> 258 | H12: =SUM(H7:H11) -> 1297
G13: CANTIDAD | H13: =SUM(H7:H11) -> 1297 | I13: BOLIVIANOS | J13: =SUM(J7:J12) -> 43175

Sheet RES 17 AL 21
D1: PERIODO DE CERTIFICACION CON EL COLEGIO "SCIS" DEL 17 AL 21 DE AGOSTO DE 2026
A5: DETALLE TURNO | C5: 46251 | D5: 46252 | E5: 46253 | F5: 46254 | G5: 46255 | H5: TOTAL PLATOS VENDIDOS | I5: IMPORTE POR PLATO BS. | J5: IMPORTE TOTAL A PAGAR BS.
A7: TURNO 1 | B7: 0.49305556 | C7: =+'11;50'!O95 -> 41 | D7: =+'11;50'!P95 -> 35 | E7: =+'11;50'!Q95 -> 33 | F7: =+'11;50'!R95 -> 34 | G7: =+'11;50'!S95 -> 30 | H7: =SUM(C7:G7) -> 173 | I7: 32 | J7: =+I7*H7 -> 5536
A8: TURNO 2 | B8: 0.5 | C8: =+'12;00'!O158 -> 64 | D8: =+'12;00'!P158 -> 55 | E8: =+'12;00'!Q158 -> 55 | F8: =+'12;00'!R158 -> 55 | G8: =+'12;00'!S158 -> 58 | H8: =SUM(C8:G8) -> 287 | I8: 32 | J8: =+I8*H8 -> 9184
A9: TURNO 3 | B9: 0.47569444 | C9: =+'11;25'!O160 -> 59 | D9: =+'11;25'!P160 -> 55 | E9: =+'11;25'!Q160 -> 54 | F9: =+'11;25'!R160 -> 62 | G9: =+'11;25'!S160 -> 61 | H9: =SUM(C9:G9) -> 291 | I9: 32 | J9: =+I9*H9 -> 9312
A10: TURNO 4 | B10: 0.52777778 | C10: =+'12;40'!O155 -> 67 | D10: =+'12;40'!P155 -> 53 | E10: =+'12;40'!Q155 -> 50 | F10: =+'12;40'!R155 -> 51 | G10: =+'12;40'!S155 -> 53 | H10: =SUM(C10:G10) -> 274 | I10: 35 | J10: =+I10*H10 -> 9590
A11: TURNO 5 | B11: 0.54513889 | C11: =+'13;05'!O156 -> 54 | D11: =+'13;05'!P156 -> 48 | E11: =+'13;05'!Q156 -> 48 | F11: =+'13;05'!R156 -> 47 | G11: =+'13;05'!S156 -> 47 | H11: =SUM(C11:G11) -> 244 | I11: 35 | J11: =+I11*H11 -> 8540
A12: TOTALES | C12: =SUM(C7:C11) -> 285 | D12: =SUM(D7:D11) -> 246 | E12: =SUM(E7:E11) -> 240 | F12: =SUM(F7:F11) -> 249 | G12: =SUM(G7:G11) -> 249
E13: CANTIDAD | H13: =SUM(H7:H11) -> 1269 | I13: BOLIVIANOS | J13: =SUM(J7:J12) -> 42162

Sheet RES 24 AL 28
D1: PERIODO DE CERTIFICACION CON EL COLEGIO "SCIS" DEL 24 AL 28 DE AGOSTO DE 2026
A5: DETALLE TURNO | C5: 46258 | D5: 46259 | E5: 46260 | F5: 46261 | G5: 46262 | H5: TOTAL PLATOS VENDIDOS | I5: IMPORTE POR PLATO BS. | J5: IMPORTE TOTAL A PAGAR BS.
A7: TURNO 1 | B7: 0.49305556 | C7: =+'11;50'!T95 -> 39 | D7: =+'11;50'!U95 -> 35 | E7: =+'11;50'!V95 -> 34 | F7: =+'11;50'!W95 -> 35 | H7: =SUM(C7:G7) -> 143 | I7: 32 | J7: =+I7*H7 -> 4576
A8: TURNO 2 | B8: 0.5 | C8: =+'12;00'!T158 -> 62 | D8: =+'12;00'!U158 -> 58 | E8: =+'12;00'!V158 -> 52 | F8: =+'12;00'!W158 -> 50 | G8: =+'12;00'!X158 -> 58 | H8: =SUM(C8:G8) -> 280 | I8: 32 | J8: =+I8*H8 -> 8960
A9: TURNO 3 | B9: 0.47569444 | C9: =+'11;25'!T160 -> 70 | D9: =+'11;25'!U160 -> 56 | E9: =+'11;25'!V160 -> 52 | F9: =+'11;25'!W160 -> 57 | G9: =+'11;25'!X160 -> 58 | H9: =SUM(C9:G9) -> 293 | I9: 32 | J9: =+I9*H9 -> 9376
A10: TURNO 4 | B10: 0.52777778 | C10: =+'12;40'!T155 -> 64 | D10: =+'12;40'!U155 -> 56 | E10: =+'12;40'!V155 -> 56 | F10: =+'12;40'!W155 -> 57 | G10: =+'12;40'!X155 -> 57 | H10: =SUM(C10:G10) -> 290 | I10: 35 | J10: =+I10*H10 -> 10150
A11: TURNO 5 | B11: 0.54513889 | C11: =+'13;05'!T156 -> 46 | D11: =+'13;05'!U156 -> 49 | E11: =+'13;05'!V156 -> 52 | F11: =+'13;05'!W156 -> 48 | G11: =+'13;05'!X156 -> 49 | H11: =SUM(C11:G11) -> 244 | I11: 35 | J11: =+I11*H11 -> 8540
A12: TOTALES | C12: =SUM(C7:C11) -> 281 | D12: =SUM(D7:D11) -> 254 | E12: =SUM(E7:E11) -> 246 | F12: =SUM(F7:F11) -> 247 | G12: =SUM(G7:G11) -> 222 | H12: =SUM(H7:H11) -> 1250
E13: CANTIDAD | H13: =SUM(H7:H12) -> 2500 | I13: BOLIVIANOS | J13: =SUM(J7:J12) -> 41602

Sheet RES 31
D1: PERIODO DE CERTIFICACION CON EL COLEGIO "SCIS" DEL 31 DE AGOSTO DE 2026
A5: DETALLE TURNO | C5: 46265 | H5: TOTAL PLATOS VENDIDOS | I5: IMPORTE POR PLATO BS. | J5: IMPORTE TOTAL A PAGAR BS.
A7: TURNO 1 | B7: 0.49305556 | C7: =+'11;50'!Y95 -> 0 | H7: =SUM(C7:G7) -> 0 | I7: 32 | J7: =+I7*H7 -> 0
A8: TURNO 2 | B8: 0.5 | C8: =+'12;00'!Y158 -> 0 | H8: =SUM(C8:G8) -> 0 | I8: 32 | J8: =+I8*H8 -> 0
A9: TURNO 3 | B9: 0.47569444 | C9: =+'11;25'!Y160 -> 0 | H9: =SUM(C9:G9) -> 0 | I9: 32 | J9: =+I9*H9 -> 0
A10: TURNO 4 | B10: 0.52777778 | C10: =+'12;40'!Y155 -> 0 | H10: =SUM(C10:G10) -> 0 | I10: 35 | J10: =+I10*H10 -> 0
A11: TURNO 5 | B11: 0.54513889 | C11: =+'13;05'!Y156 -> 0 | H11: =SUM(C11:G11) -> 0 | I11: 35 | J11: =+I11*H11 -> 0
A12: TOTALES | C12: =SUM(C7:C11) -> 0 | D12: =SUM(D7:D11) -> 0 | E12: =SUM(E7:E11) -> 0 | F12: =SUM(F7:F11) -> 0 | G12: =SUM(G7:G11) -> 0 | H12: =SUM(H7:H11) -> 0
E13: CANTIDAD | H13: =SUM(H7:H12) -> 0 | I13: BOLIVIANOS | J13: =SUM(J7:J12) -> 0
